Workbook
Name TblAPIFactory: 'API Raw'!$E$11:$G$32
Name TblAPIHQ: 'API Raw'!$S$11:$AQ$11
Name TblAPIMines: 'API Raw'!$N$30:$AO$51
Name TblAPISpecial: 'API Raw'!$P$11:$Q$24
Name TblAPIWarehouse: 'API Raw'!$J$11:$L$76
Name TblFactoryBasics: Static!$B$4:$E$25
Name TblFactoryInput: Static!$H$4:$J$68
Name TblFactoryUpgrades: Static!$M$4:$O$89
Name TblMarket: Markets!$F$4:$J$61
Name TblMineBasics: Static!$R$4:$Y$17
Name TblRecycleBasics: Static!$AH$23:$AQ$32
Name TblResourcesType: Static!$AB$4:$AE$61
Name TblSpecialBasics: Static!$AH$3:$AO$17
Name TblUserFactories: UserBuildings!$K$5:$L$26
Name TblUserMines: UserBuildings!$B$5:$I$18
Name TblUserWarehouse: UserBuildings!$Y$5:$AA$40

Sheet Supply Chain
B1: Profit Totals | C1: Daily All | D1: Daily Mine | E1: Daily Factory | F1: Hourly All | I1: Hourly Mine | J1: Hourly Factory | K1: Minute All | L1: Second All
B2: Adj For Use | C2: =M57-MAX(UserBuildings!B26:E26) -> #N/A | D2: =E48 -> 4.9211496e+11 | E2: =M56 -> #N/A | F2: =J57-(MAX(UserBuildings!B26:E26)/24) -> #N/A | I2: =C48 -> 1.0342045e+10 | J2: =J56 -> #N/A | K2: =F2/60 -> #N/A | L2: =K2/60 -> #N/A
B4: Biggest shortages - Production
B6: Resource | C6: Avg production/hour | D6: Required/hour | E6: Ratio @100% maint | F6: Daily Purchase Req | G6: WH LV | I6: Product | J6: Produce_Hr | K6: Req_Hr | L6: Ratio @100% Use | M6: Daily Purchase Req | N6: WH LV
B7: Clay | C7: =VLOOKUP(B7,TblUserMines,6,FALSE) -> 35844.48 | D7: =SUMIFS(Calc!$I$4:$I$100,Calc!$H$4:$H$100,B7) -> 427200 | E7: =IFERROR(D7/C7,"BUYALL") -> 11.918153 | F7: =IF(((D7-C7)*24)<0,0,((D7-C7)*24)) -> 9392532.5 | G7: =IF(ROUNDUP(SQRT((D7*24)/5000),0)<ROUNDUP(SQRT((C7*24)/5000),0),ROUNDUP(SQRT((C7*24)/5000),0),ROUNDUP(SQRT((D7*24)/5000),0)) -> 46 | I7: =Calc!C4 -> Bricks | J7: =Calc!D4 -> 284800 | K7: =Calc!M4 -> 0 | L7: =IFERROR(K7/J7,0) -> 0 | M7: =IF(((K7-J7)*24)<0,0,((K7-J7)*24)) -> 0 | N7: =IF(ROUNDUP(SQRT((K7*24)/5000),0)<ROUNDUP(SQRT((J7*24)/5000),0),ROUNDUP(SQRT((J7*24)/5000),0),ROUNDUP(SQRT((K7*24)/5000),0)) -> 37
B8: Limestone | C8: =VLOOKUP(B8,TblUserMines,6,FALSE) -> 3686.76 | D8: =SUMIFS(Calc!$I$4:$I$100,Calc!$H$4:$H$100,B8) -> 129560 | E8: =IFERROR(D8/C8,"BUYALL") -> 35.141967 | F8: =IF(((D8-C8)*24)<0,0,((D8-C8)*24)) -> 3020957.8 | G8: =IF(ROUNDUP(SQRT((D8*24)/5000),0)<ROUNDUP(SQRT((C8*24)/5000),0),ROUNDUP(SQRT((C8*24)/5000),0),ROUNDUP(SQRT((D8*24)/5000),0)) -> 25 | I8: =Calc!C5 -> Concrete | J8: =Calc!D5 -> 327600 | K8: =Calc!M5 -> 0 | L8: =IFERROR(K8/J8,0) -> 0 | M8: =IF(((K8-J8)*24)<0,0,((K8-J8)*24)) -> 0 | N8: =IF(ROUNDUP(SQRT((K8*24)/5000),0)<ROUNDUP(SQRT((J8*24)/5000),0),ROUNDUP(SQRT((J8*24)/5000),0),ROUNDUP(SQRT((K8*24)/5000),0)) -> 40
B9: Gravel | C9: =VLOOKUP(B9,TblUserMines,6,FALSE) -> 0 | D9: =SUMIFS(Calc!$I$4:$I$100,Calc!$H$4:$H$100,B9) -> 70200 | E9: =IFERROR(D9/C9,"BUYALL") -> BUYALL | F9: =IF(((D9-C9)*24)<0,0,((D9-C9)*24)) -> 1684800 | G9: =IF(ROUNDUP(SQRT((D9*24)/5000),0)<ROUNDUP(SQRT((C9*24)/5000),0),ROUNDUP(SQRT((C9*24)/5000),0),ROUNDUP(SQRT((D9*24)/5000),0)) -> 19 | I9: =Calc!C6 -> Fertilizer | J9: =Calc!D6 -> 77440 | K9: =Calc!M6 -> 0 | L9: =IFERROR(K9/J9,0) -> 0 | M9: =IF(((K9-J9)*24)<0,0,((K9-J9)*24)) -> 0 | N9: =IF(ROUNDUP(SQRT((K9*24)/5000),0)<ROUNDUP(SQRT((J9*24)/5000),0),ROUNDUP(SQRT((J9*24)/5000),0),ROUNDUP(SQRT((K9*24)/5000),0)) -> 20
B10: Coal | C10: =VLOOKUP(B10,TblUserMines,6,FALSE) -> 270153.66 | D10: =SUMIFS(Calc!$I$4:$I$100,Calc!$H$4:$H$100,B10) -> 292500 | E10: =IFERROR(D10/C10,"BUYALL") -> 1.0827171 | F10: =IF(((D10-C10)*24)<0,0,((D10-C10)*24)) -> 536312.16 | G10: =IF(ROUNDUP(SQRT((D10*24)/5000),0)<ROUNDUP(SQRT((C10*24)/5000),0),ROUNDUP(SQRT((C10*24)/5000),0),ROUNDUP(SQRT((D10*24)/5000),0)) -> 38 | I10: =Calc!C7 -> Steel | J10: =Calc!D7 -> 29250 | K10: =Calc!M7 -> 2100 | L10: =IFERROR(K10/J10,0) -> 0.071794872 | M10: =IF(((K10-J10)*24)<0,0,((K10-J10)*24)) -> 0 | N10: =IF(ROUNDUP(SQRT((K10*24)/5000),0)<ROUNDUP(SQRT((J10*24)/5000),0),ROUNDUP(SQRT((J10*24)/5000),0),ROUNDUP(SQRT((K10*24)/5000),0)) -> 12
B11: Iron Ore | C11: =VLOOKUP(B11,TblUserMines,6,FALSE) -> 132299.02 | D11: =SUMIFS(Calc!$I$4:$I$100,Calc!$H$4:$H$100,B11) -> 204750 | E11: =IFERROR(D11/C11,"BUYALL") -> 1.5476305 | F11: =IF(((D11-C11)*24)<0,0,((D11-C11)*24)) -> 1738823.5 | G11: =IF(ROUNDUP(SQRT((D11*24)/5000),0)<ROUNDUP(SQRT((C11*24)/5000),0),ROUNDUP(SQRT((C11*24)/5000),0),ROUNDUP(SQRT((D11*24)/5000),0)) -> 32 | I11: =Calc!C8 -> Fossil fuel | J11: =Calc!D8 -> 40320 | K11: =Calc!M8 -> 30080 | L11: =IFERROR(K11/J11,0) -> 0.74603175 | M11: =IF(((K11-J11)*24)<0,0,((K11-J11)*24)) -> 0 | N11: =IF(ROUNDUP(SQRT((K11*24)/5000),0)<ROUNDUP(SQRT((J11*24)/5000),0),ROUNDUP(SQRT((J11*24)/5000),0),ROUNDUP(SQRT((K11*24)/5000),0)) -> 14
B12: Crude Oil | C12: =VLOOKUP(B12,TblUserMines,6,FALSE) -> 6979.56 | D12: =SUMIFS(Calc!$I$4:$I$100,Calc!$H$4:$H$100,B12) -> 47700 | E12: =IFERROR(D12/C12,"BUYALL") -> 6.8342417 | F12: =IF(((D12-C12)*24)<0,0,((D12-C12)*24)) -> 977290.56 | G12: =IF(ROUNDUP(SQRT((D12*24)/5000),0)<ROUNDUP(SQRT((C12*24)/5000),0),ROUNDUP(SQRT((C12*24)/5000),0),ROUNDUP(SQRT((D12*24)/5000),0)) -> 16 | I12: =Calc!C9 -> Glass | J12: =Calc!D9 -> 30080 | K12: =Calc!M9 -> 0 | L12: =IFERROR(K12/J12,0) -> 0 | M12: =IF(((K12-J12)*24)<0,0,((K12-J12)*24)) -> 0 | N12: =IF(ROUNDUP(SQRT((K12*24)/5000),0)<ROUNDUP(SQRT((J12*24)/5000),0),ROUNDUP(SQRT((J12*24)/5000),0),ROUNDUP(SQRT((K12*24)/5000),0)) -> 13
B13: Quartz Sand | C13: =VLOOKUP(B13,TblUserMines,6,FALSE) -> 0 | D13: =SUMIFS(Calc!$I$4:$I$100,Calc!$H$4:$H$100,B13) -> 22560 | E13: =IFERROR(D13/C13,"BUYALL") -> BUYALL | F13: =IF(((D13-C13)*24)<0,0,((D13-C13)*24)) -> 541440 | G13: =IF(ROUNDUP(SQRT((D13*24)/5000),0)<ROUNDUP(SQRT((C13*24)/5000),0),ROUNDUP(SQRT((C13*24)/5000),0),ROUNDUP(SQRT((D13*24)/5000),0)) -> 11 | I13: =Calc!C10 -> Copper | J13: =Calc!D10 -> 11340 | K13: =Calc!M10 -> 10280 | L13: =IFERROR(K13/J13,0) -> 0.90652557 | M13: =IF(((K13-J13)*24)<0,0,((K13-J13)*24)) -> 0 | N13: =IF(ROUNDUP(SQRT((K13*24)/5000),0)<ROUNDUP(SQRT((J13*24)/5000),0),ROUNDUP(SQRT((J13*24)/5000),0),ROUNDUP(SQRT((K13*24)/5000),0)) -> 8
B14: Chalcopyrite | C14: =VLOOKUP(B14,TblUserMines,6,FALSE) -> 0 | D14: =SUMIFS(Calc!$I$4:$I$100,Calc!$H$4:$H$100,B14) -> 34020 | E14: =IFERROR(D14/C14,"BUYALL") -> BUYALL | F14: =IF(((D14-C14)*24)<0,0,((D14-C14)*24)) -> 816480 | G14: =IF(ROUNDUP(SQRT((D14*24)/5000),0)<ROUNDUP(SQRT((C14*24)/5000),0),ROUNDUP(SQRT((C14*24)/5000),0),ROUNDUP(SQRT((D14*24)/5000),0)) -> 13 | I14: =Calc!C11 -> Insecticides | J14: =Calc!D11 -> 133000 | K14: =Calc!M11 -> 0 | L14: =IFERROR(K14/J14,0) -> 0 | M14: =IF(((K14-J14)*24)<0,0,((K14-J14)*24)) -> 0 | N14: =IF(ROUNDUP(SQRT((K14*24)/5000),0)<ROUNDUP(SQRT((J14*24)/5000),0),ROUNDUP(SQRT((J14*24)/5000),0),ROUNDUP(SQRT((K14*24)/5000),0)) -> 26
B15: Bauxite | C15: =VLOOKUP(B15,TblUserMines,6,FALSE) -> 7239.26 | D15: =SUMIFS(Calc!$I$4:$I$100,Calc!$H$4:$H$100,B15) -> 88320 | E15: =IFERROR(D15/C15,"BUYALL") -> 12.200142 | F15: =IF(((D15-C15)*24)<0,0,((D15-C15)*24)) -> 1945937.8 | G15: =IF(ROUNDUP(SQRT((D15*24)/5000),0)<ROUNDUP(SQRT((C15*24)/5000),0),ROUNDUP(SQRT((C15*24)/5000),0),ROUNDUP(SQRT((D15*24)/5000),0)) -> 21 | I15: =Calc!C12 -> Aluminium | J15: =Calc!D12 -> 14720 | K15: =Calc!M12 -> 10300 | L15: =IFERROR(K15/J15,0) -> 0.69972826 | M15: =IF(((K15-J15)*24)<0,0,((K15-J15)*24)) -> 0 | N15: =IF(ROUNDUP(SQRT((K15*24)/5000),0)<ROUNDUP(SQRT((J15*24)/5000),0),ROUNDUP(SQRT((J15*24)/5000),0),ROUNDUP(SQRT((K15*24)/5000),0)) -> 9
B16: Lithium Ore | C16: =VLOOKUP(B16,TblUserMines,6,FALSE) -> 3194800 | D16: =SUMIFS(Calc!$I$4:$I$100,Calc!$H$4:$H$100,B16) -> 621000 | E16: =IFERROR(D16/C16,"BUYALL") -> 0.19437836 | F16: =IF(((D16-C16)*24)<0,0,((D16-C16)*24)) -> 0 | G16: =IF(ROUNDUP(SQRT((D16*24)/5000),0)<ROUNDUP(SQRT((C16*24)/5000),0),ROUNDUP(SQRT((C16*24)/5000),0),ROUNDUP(SQRT((D16*24)/5000),0)) -> 124 | I16: =Calc!C13 -> Plastics | J16: =Calc!D13 -> 73800 | K16: =Calc!M13 -> 51760 | L16: =IFERROR(K16/J16,0) -> 0.70135501 | M16: =IF(((K16-J16)*24)<0,0,((K16-J16)*24)) -> 0 | N16: =IF(ROUNDUP(SQRT((K16*24)/5000),0)<ROUNDUP(SQRT((J16*24)/5000),0),ROUNDUP(SQRT((J16*24)/5000),0),ROUNDUP(SQRT((K16*24)/5000),0)) -> 19
B17: Ilmenite | C17: =VLOOKUP(B17,TblUserMines,6,FALSE) -> 0 | D17: =SUMIFS(Calc!$I$4:$I$100,Calc!$H$4:$H$100,B17) -> 13440 | E17: =IFERROR(D17/C17,"BUYALL") -> BUYALL | F17: =IF(((D17-C17)*24)<0,0,((D17-C17)*24)) -> 322560 | G17: =IF(ROUNDUP(SQRT((D17*24)/5000),0)<ROUNDUP(SQRT((C17*24)/5000),0),ROUNDUP(SQRT((C17*24)/5000),0),ROUNDUP(SQRT((D17*24)/5000),0)) -> 9 | I17: =Calc!C14 -> Lithium | J17: =Calc!D14 -> 27000 | K17: =Calc!M14 -> 20400 | L17: =IFERROR(K17/J17,0) -> 0.75555556 | M17: =IF(((K17-J17)*24)<0,0,((K17-J17)*24)) -> 0 | N17: =IF(ROUNDUP(SQRT((K17*24)/5000),0)<ROUNDUP(SQRT((J17*24)/5000),0),ROUNDUP(SQRT((J17*24)/5000),0),ROUNDUP(SQRT((K17*24)/5000),0)) -> 12
B18: Silver Ore | C18: =VLOOKUP(B18,TblUserMines,6,FALSE) -> 32797.66 | D18: =SUMIFS(Calc!$I$4:$I$100,Calc!$H$4:$H$100,B18) -> 5760 | E18: =IFERROR(D18/C18,"BUYALL") -> 0.17562229 | F18: =IF(((D18-C18)*24)<0,0,((D18-C18)*24)) -> 0 | G18: =IF(ROUNDUP(SQRT((D18*24)/5000),0)<ROUNDUP(SQRT((C18*24)/5000),0),ROUNDUP(SQRT((C18*24)/5000),0),ROUNDUP(SQRT((D18*24)/5000),0)) -> 13 | I18: =Calc!C15 -> Batteries | J18: =Calc!D15 -> 10200 | K18: =Calc!M15 -> 600 | L18: =IFERROR(K18/J18,0) -> 0.058823529 | M18: =IF(((K18-J18)*24)<0,0,((K18-J18)*24)) -> 0 | N18: =IF(ROUNDUP(SQRT((K18*24)/5000),0)<ROUNDUP(SQRT((J18*24)/5000),0),ROUNDUP(SQRT((J18*24)/5000),0),ROUNDUP(SQRT((K18*24)/5000),0)) -> 7
... B20: Rough Diamonds | C20: =VLOOKUP(B20,TblUserMines,6,FALSE) -> 5174400 | D20: =SUMIFS(Calc!$I$4:$I$100,Calc!$H$4:$H$100,B20) -> 2400000 | E20: =IFERROR(D20/C20,"BUYALL") -> 0.46382189 | F20: =IF(((D20-C20)*24)<0,0,((D20-C20)*24)) -> 0 | G20: =IF(ROUNDUP(SQRT((D20*24)/5000),0)<ROUNDUP(SQRT((C20*24)/5000),0),ROUNDUP(SQRT((C20*24)/5000),0),ROUNDUP(SQRT((D20*24)/5000),0)) -> 158 | I20: =Calc!C17 -> Silicon | J20: =Calc!D17 -> 0 | K20: =Calc!M17 -> 2160 | L20: =IFERROR(K20/J20,0) -> 0 | M20: =IF(((K20-J20)*24)<0,0,((K20-J20)*24)) -> 51840 | N20: =IF(ROUNDUP(SQRT((K20*24)/5000),0)<ROUNDUP(SQRT((J20*24)/5000),0),ROUNDUP(SQRT((J20*24)/5000),0),ROUNDUP(SQRT((K20*24)/5000),0)) -> 4
I21: =Calc!C18 -> Electronics | J21: =Calc!D18 -> 17280 | K21: =Calc!M18 -> 2320 | L21: =IFERROR(K21/J21,0) -> 0.13425926 | M21: =IF(((K21-J21)*24)<0,0,((K21-J21)*24)) -> 0 | N21: =IF(ROUNDUP(SQRT((K21*24)/5000),0)<ROUNDUP(SQRT((J21*24)/5000),0),ROUNDUP(SQRT((J21*24)/5000),0),ROUNDUP(SQRT((K21*24)/5000),0)) -> 10
I22: =Calc!C19 -> Titanium | J22: =Calc!D19 -> 6720 | K22: =Calc!M19 -> 4640 | L22: =IFERROR(K22/J22,0) -> 0.69047619 | M22: =IF(((K22-J22)*24)<0,0,((K22-J22)*24)) -> 0 | N22: =IF(ROUNDUP(SQRT((K22*24)/5000),0)<ROUNDUP(SQRT((J22*24)/5000),0),ROUNDUP(SQRT((J22*24)/5000),0),ROUNDUP(SQRT((K22*24)/5000),0)) -> 6
I23: =Calc!C20 -> Medical technology | J23: =Calc!D20 -> 11600 | K23: =Calc!M20 -> 0 | L23: =IFERROR(K23/J23,0) -> 0 | M23: =IF(((K23-J23)*24)<0,0,((K23-J23)*24)) -> 0 | N23: =IF(ROUNDUP(SQRT((K23*24)/5000),0)<ROUNDUP(SQRT((J23*24)/5000),0),ROUNDUP(SQRT((J23*24)/5000),0),ROUNDUP(SQRT((K23*24)/5000),0)) -> 8
I24: =Calc!C21 -> Silver | J24: =Calc!D21 -> 36000 | K24: =Calc!M21 -> 3400 | L24: =IFERROR(K24/J24,0) -> 0.094444444 | M24: =IF(((K24-J24)*24)<0,0,((K24-J24)*24)) -> 0 | N24: =IF(ROUNDUP(SQRT((K24*24)/5000),0)<ROUNDUP(SQRT((J24*24)/5000),0),ROUNDUP(SQRT((J24*24)/5000),0),ROUNDUP(SQRT((K24*24)/5000),0)) -> 14
I25: =Calc!C22 -> Gold | J25: =Calc!D22 -> 5040 | K25: =Calc!M22 -> 2400 | L25: =IFERROR(K25/J25,0) -> 0.47619048 | M25: =IF(((K25-J25)*24)<0,0,((K25-J25)*24)) -> 0 | N25: =IF(ROUNDUP(SQRT((K25*24)/5000),0)<ROUNDUP(SQRT((J25*24)/5000),0),ROUNDUP(SQRT((J25*24)/5000),0),ROUNDUP(SQRT((K25*24)/5000),0)) -> 5
I26: =Calc!C23 -> Jewellery | J26: =Calc!D23 -> 4800 | K26: =Calc!M23 -> 0 | L26: =IFERROR(K26/J26,0) -> 0 | M26: =IF(((K26-J26)*24)<0,0,((K26-J26)*24)) -> 0 | N26: =IF(ROUNDUP(SQRT((K26*24)/5000),0)<ROUNDUP(SQRT((J26*24)/5000),0),ROUNDUP(SQRT((J26*24)/5000),0),ROUNDUP(SQRT((K26*24)/5000),0)) -> 5
I27: =Calc!C24 -> Scan drones | J27: =Calc!D24 -> 0 | K27: =Calc!M24 -> 0 | L27: =IFERROR(K27/J27,0) -> 0 | M27: =IF(((K27-J27)*24)<0,0,((K27-J27)*24)) -> 0 | N27: =IF(ROUNDUP(SQRT((K27*24)/5000),0)<ROUNDUP(SQRT((J27*24)/5000),0),ROUNDUP(SQRT((J27*24)/5000),0),ROUNDUP(SQRT((K27*24)/5000),0)) -> 0
I28: Trucks | J28: =Calc!D25 -> 1000 | K28: =Calc!M25 -> 0 | L28: =IFERROR(K28/J28,0) -> 0 | M28: =IF(((K28-J28)*24)<0,0,((K28-J28)*24)) -> 0 | N28: =IF(ROUNDUP(SQRT((K28*24)/5000),0)<ROUNDUP(SQRT((J28*24)/5000),0),ROUNDUP(SQRT((J28*24)/5000),0),ROUNDUP(SQRT((K28*24)/5000),0)) -> 3
B30: Profit centers
B32: Value at hand | C32: Adj Value/hr | D32: Value/hr | E32: Individ VL | I32: Product | J32: Adj Value/hr | K32: Value/hr | L32: Individ VL | M32: Profit Ratio | N32: Actual Profit | P32: Profit/hr
B33: Clay | C33: =VLOOKUP($B33,Markets!$F$4:$J$61,5,FALSE)*(C7-D7) -> -136974432 | D33: =VLOOKUP($B33,TblMarket,5,FALSE)*C7 -> 12545568 | E33: =IF(VLOOKUP($B33,Markets!$F$4:$H$61,3,FALSE)=0,VLOOKUP($B33,Markets!$F$4:$H$61,2,FALSE), VLOOKUP($B33,Markets!$F$4:$H$61,3,FALSE)) -> 350 | I33: Bricks | J33: =VLOOKUP($I33,TblMarket,5,FALSE)*(J7-K7) -> #N/A | K33: =VLOOKUP($I33,TblMarket,5,FALSE)*J7 -> #N/A | L33: =VLOOKUP($I33,TblMarket,5,FALSE) -> #N/A | M33: =(L33*2)/(E33*3+10) -> #N/A | N33: =(L33)-(E33*3+10)/2 -> #N/A | P33: =Calc!D4*N33 -> #N/A
B34: Limestone | C34: =VLOOKUP($B34,TblMarket,5,FALSE)*(C8-D8) -> -64447099 | D34: =VLOOKUP($B34,TblMarket,5,FALSE)*C8 -> 1887621.1 | E34: =IF(VLOOKUP($B34,Markets!$F$4:$H$61,3,FALSE)=0,VLOOKUP($B34,Markets!$F$4:$H$61,2,FALSE), VLOOKUP($B34,Markets!$F$4:$H$61,3,FALSE)) -> 512 | I34: Concrete | J34: =VLOOKUP($I34,TblMarket,5,FALSE)*(J8-K8) -> 1695657600 | K34: =VLOOKUP($I34,TblMarket,5,FALSE)*J8 -> 1695657600 | L34: =VLOOKUP($I34,TblMarket,5,FALSE) -> 5176 | M34: =(L34*14)/(E34*2+E35*3+20) -> 29.172303 | N34: =(L34)-(E34*2+E35*3+20)/14 -> 4998.5714 | P34: =Calc!D5*N34 -> 1637532000
B35: Gravel | C35: =VLOOKUP($B35,TblMarket,5,FALSE)*(C9-D9) -> -33696000 | D35: =VLOOKUP($B35,TblMarket,5,FALSE)*C9 -> 0 | E35: =IF(VLOOKUP($B35,Markets!$F$4:$H$61,3,FALSE)=0,VLOOKUP($B35,Markets!$F$4:$H$61,2,FALSE), VLOOKUP($B35,Markets!$F$4:$H$61,3,FALSE)) -> 480 | I35: Fertilizer | J35: =VLOOKUP($I35,TblMarket,5,FALSE)*(J9-K9) -> 168122240 | K35: =VLOOKUP($I35,TblMarket,5,FALSE)*J9 -> 168122240 | L35: =VLOOKUP($I35,TblMarket,5,FALSE) -> 2171 | M35: =(L35*11)/(E34*8+90) -> 5.7049689 | N35: =(L35)-(E34*8+90)/11 -> 1790.4545 | P35: =Calc!D6*N35 -> 138652800
B36: Coal | C36: =VLOOKUP($B36,TblMarket,5,FALSE)*(C10-D10) -> -54301606 | D36: =VLOOKUP($B36,TblMarket,5,FALSE)*C10 -> 6.5647339e+08 | E36: =IF(VLOOKUP($B36,Markets!$F$4:$H$61,3,FALSE)=0,VLOOKUP($B36,Markets!$F$4:$H$61,2,FALSE), VLOOKUP($B36,Markets!$F$4:$H$61,3,FALSE)) -> 2416 | I36: Steel | J36: =VLOOKUP($I36,TblMarket,5,FALSE)*(J10-K10) -> 1341753000 | K36: =VLOOKUP($I36,TblMarket,5,FALSE)*J10 -> 1445535000 | L36: =VLOOKUP($I36,TblMarket,5,FALSE) -> 49420 | M36: =L36/(E36*10+E37*7+350) -> 1.447484 | N36: =L36-(E36*10+E37*7+350) -> 15278 | P36: =Calc!D7*N36 -> 446881500
B37: Iron Ore | C37: =VLOOKUP($B37,TblMarket,5,FALSE)*(C11-D11) -> -99692548 | D37: =VLOOKUP($B37,TblMarket,5,FALSE)*C11 -> 1.8204345e+08 | E37: =IF(VLOOKUP($B37,Markets!$F$4:$H$61,3,FALSE)=0,VLOOKUP($B37,Markets!$F$4:$H$61,2,FALSE), VLOOKUP($B37,Markets!$F$4:$H$61,3,FALSE)) -> 1376 | I37: Fossil fuel | J37: =VLOOKUP($I37,TblMarket,5,FALSE)*(J11-K11) -> 329041920 | K37: =VLOOKUP($I37,TblMarket,5,FALSE)*J11 -> 1295602560 | L37: =VLOOKUP($I37,TblMarket,5,FALSE) -> 32133 | M37: =(L37*4)/(E38*4+150) -> 12.285605 | N37: =(L37)-(E38*4+150)/4 -> 29517.5 | P37: =Calc!D8*N37 -> 1190145600
B38: Crude Oil | C38: =VLOOKUP($B38,TblMarket,5,FALSE)*(C12-D12) -> -1.0497729e+08 | D38: =VLOOKUP($B38,TblMarket,5,FALSE)*C12 -> 17993306 | E38: =IF(VLOOKUP($B38,Markets!$F$4:$H$61,3,FALSE)=0,VLOOKUP($B38,Markets!$F$4:$H$61,2,FALSE), VLOOKUP($B38,Markets!$F$4:$H$61,3,FALSE)) -> 2578 | I38: Glass | J38: =VLOOKUP($I38,TblMarket,5,FALSE)*(J12-K12) -> 1510286720 | K38: =VLOOKUP($I38,TblMarket,5,FALSE)*J12 -> 1510286720 | L38: =VLOOKUP($I38,TblMarket,5,FALSE) -> 50209 | M38: =(L38*8)/(E39*6+L37*8+E34*4+3000) -> 1.5200224 | N38: =(L38)-(E39*6+L37*8+E34*4+3000)/8 -> 17177.25 | P38: =Calc!D9*N38 -> 516691680
B39: Quartz Sand | C39: =VLOOKUP($B39,TblMarket,5,FALSE)*(C13-D13) -> -8053920 | D39: =VLOOKUP($B39,TblMarket,5,FALSE)*C13 -> 0 | E39: =IF(VLOOKUP($B39,Markets!$F$4:$H$61,3,FALSE)=0,VLOOKUP($B39,Markets!$F$4:$H$61,2,FALSE), VLOOKUP($B39,Markets!$F$4:$H$61,3,FALSE)) -> 357 | I39: Copper | J39: =VLOOKUP($I39,TblMarket,5,FALSE)*(J13-K13) -> 92575100 | K39: =VLOOKUP($I39,TblMarket,5,FALSE)*J13 -> 990378900 | L39: =VLOOKUP($I39,TblMarket,5,FALSE) -> 87335 | M39: =(L39*3)/(E40*9+2500) -> 17.807721 | N39: =(L39)-(E40*9+2500)/3 -> 82430.667 | P39: =Calc!D10*N39 -> 934763760
B40: Chalcopyrite | C40: =VLOOKUP($B40,TblMarket,5,FALSE)*(C14-D14) -> -46165140 | D40: =VLOOKUP($B40,TblMarket,5,FALSE)*C14 -> 0 | E40: =IF(VLOOKUP($B40,Markets!$F$4:$H$61,3,FALSE)=0,VLOOKUP($B40,Markets!$F$4:$H$61,2,FALSE), VLOOKUP($B40,Markets!$F$4:$H$61,3,FALSE)) -> 1357 | I40: Insecticides | J40: =VLOOKUP($I40,TblMarket,5,FALSE)*(J14-K14) -> 580146000 | K40: =VLOOKUP($I40,TblMarket,5,FALSE)*J14 -> 580146000 | L40: =VLOOKUP($I40,TblMarket,5,FALSE) -> 4362 | M40: =(L40*35)/(E34*3+L39+2400) -> 1.6727109 | N40: =(L40)-(E34*3+L39+2400)/35 -> 1754.2571 | P40: =Calc!D11*N40 -> 233316200
B41: Bauxite | C41: =VLOOKUP($B41,TblMarket,5,FALSE)*(C15-D15) -> -1.662966e+08 | D41: =VLOOKUP($B41,TblMarket,5,FALSE)*C15 -> 14847722 | E41: =IF(VLOOKUP($B41,Markets!$F$4:$H$61,3,FALSE)=0,VLOOKUP($B41,Markets!$F$4:$H$61,2,FALSE), VLOOKUP($B41,Markets!$F$4:$H$61,3,FALSE)) -> 2050 | I41: Aluminium | J41: =VLOOKUP($I41,TblMarket,5,FALSE)*(J15-K15) -> 426101260 | K41: =VLOOKUP($I41,TblMarket,5,FALSE)*J15 -> 1419052160 | L41: =VLOOKUP($I41,TblMarket,5,FALSE) -> 96403 | M41: =(L41*4)/(E41*24+5000) -> 7.1146125 | N41: =(L41)-(E41*24+5000)/4 -> 82853 | P41: =Calc!D12*N41 -> 1219596160
B42: Lithium Ore | C42: =VLOOKUP($B42,TblMarket,5,FALSE)*(C16-D16) -> 1253440600 | D42: =VLOOKUP($B42,TblMarket,5,FALSE)*C16 -> 1555867600 | E42: =IF(VLOOKUP($B42,Markets!$F$4:$H$61,3,FALSE)=0,VLOOKUP($B42,Markets!$F$4:$H$61,2,FALSE), VLOOKUP($B42,Markets!$F$4:$H$61,3,FALSE)) -> 487 | I42: Plastics | J42: =VLOOKUP($I42,TblMarket,5,FALSE)*(J16-K16) -> 105836080 | K42: =VLOOKUP($I42,TblMarket,5,FALSE)*J16 -> 354387600 | L42: =VLOOKUP($I42,TblMarket,5,FALSE) -> 4802 | M42: =(L42*10)/(E38+400) -> 16.124916 | N42: =(L42)-(E38+400)/10 -> 4504.2 | P42: =Calc!D13*N42 -> 332409960
B43: Ilmenite | C43: =VLOOKUP($B43,TblMarket,5,FALSE)*(C17-D17) -> -4032000 | D43: =VLOOKUP($B43,TblMarket,5,FALSE)*C17 -> 0 | E43: =IF(VLOOKUP($B43,Markets!$F$4:$H$61,3,FALSE)=0,VLOOKUP($B43,Markets!$F$4:$H$61,2,FALSE), VLOOKUP($B43,Markets!$F$4:$H$61,3,FALSE)) -> 300 | I43: Lithium | J43: =VLOOKUP($I43,TblMarket,5,FALSE)*(J17-K17) -> 201234000 | K43: =VLOOKUP($I43,TblMarket,5,FALSE)*J17 -> 823230000 | L43: =VLOOKUP($I43,TblMarket,5,FALSE) -> 30490 | M43: =(L43*5)/(E42*115+5000) -> 2.4989755 | N43: =(L43)-(E42*115+5000)/5 -> 18289 | P43: =Calc!D14*N43 -> 493803000
B44: Silver Ore | C44: =VLOOKUP($B44,TblMarket,5,FALSE)*(C18-D18) -> 40853904 | D44: =VLOOKUP($B44,TblMarket,5,FALSE)*C18 -> 49557264 | E44: =IF(VLOOKUP($B44,Markets!$F$4:$H$61,3,FALSE)=0,VLOOKUP($B44,Markets!$F$4:$H$61,2,FALSE), VLOOKUP($B44,Markets!$F$4:$H$61,3,FALSE)) -> 1511 | I44: Batteries | J44: =VLOOKUP($I44,TblMarket,5,FALSE)*(J18-K18) -> 1983292800 | K44: =VLOOKUP($I44,TblMarket,5,FALSE)*J18 -> 2107248600 | L44: =VLOOKUP($I44,TblMarket,5,FALSE) -> 206593 | M44: =(L44*10)/(L43*20+L42*40+L41*10+75000) -> 1.122233 | N44: =L44-(L43*20+L42*40+L41*10+75000)/10 -> 22502 | P44: =Calc!D15*N44 -> 229520400
B45: Gold Ore | C45: =VLOOKUP($B45,TblMarket,5,FALSE)*(C19-D19) -> 3.0554747e+08 | D45: =VLOOKUP($B45,TblMarket,5,FALSE)*C19 -> 3.3753467e+08 | E45: =IF(VLOOKUP($B45,Markets!$F$4:$H$61,3,FALSE)=0,VLOOKUP($B45,Markets!$F$4:$H$61,2,FALSE), VLOOKUP($B45,Markets!$F$4:$H$61,3,FALSE)) -> 952 | I45: Weapons | J45: =VLOOKUP($I45,TblMarket,5,FALSE)*(J19-K19) -> #N/A | K45: =VLOOKUP($I45,TblMarket,5,FALSE)*J19 -> #N/A | L45: =VLOOKUP($I45,TblMarket,5,FALSE) -> #N/A | M45: =(L45*25)/(L36+L41+L44+250000) -> #N/A | N45: =(L45)-(L36+L41+L44+250000)/25 -> #N/A | P45: =Calc!D16*N45 -> #N/A
...

Sheet UserBuildings
B1: Fill the blue highlighted areas with your current stats. | Y1: Warehouse level is optional. To leave this out of calculations, put it all to zero.
B2: API Toggle: | C2: 0 | D2: API Credits Left: | E2: ='API Raw'!B11 -> 0 | F2: API Key: | G2: d2f7070074a24ff4c55a55a0c0ab3faa699c437a4d87b
B3: Mines | C3: fill from mine overview | K3: Factories | R3: Buildings | W3: HQ | Y3: Warehouse
B4: Resource | C4: Mine name | D4: Number: | E4: Manual | F4: API | G4: Average Produce | H4: Max Production | I4: Max from API | K4: Name | L4: Use Lvl | M4: Actual Lvl | N4: Manual Lvl | O4: API Lvl | P4: Using? | R4: Name | S4: Lvl | T4: Manual Lvl | U4: API Lvl | W4: Level | Y4: Resource | Z4: Level | AA4: Manual Lvl | AB4: API Lvl
B5: Clay | C5: Clay pit | D5: =IF(F5=0,E5,F5) -> 25 | E5: 25 | F5: =IFERROR(VLOOKUP(C5,TblAPIMines,2,FALSE),0) -> 0 | G5: =IF(I5=0,H5*$G$20/100,I5*$G$20/100) -> 35844.48 | H5: 36576 | I5: =IFERROR(VLOOKUP(C5,TblAPIMines,5,FALSE),0) -> 0 | K5: Brick factory | L5: =IF(P5="NO",0,M5) -> 356 | M5: =IF(O5=0,N5,O5) -> 356 | N5: 356 | O5: =IFERROR(VLOOKUP(K5,TblAPIFactory,2,FALSE),0) -> 0 | P5: Yes | R5: Tech center | S5: =IF(U5=0,T5,U5) -> 10 | T5: 10 | U5: =IFERROR(VLOOKUP(R5,TblAPISpecial,2,FALSE),0) -> 0 | W5: =IF(W7=0,W6,W7) -> 9 | Y5: Bauxite | Z5: =IF(AB5=0,AA5,AB5) -> 32 | AA5: 32 | AB5: =IFERROR(VLOOKUP(Y5,TblAPIWarehouse,2,FALSE),0) -> 0
B6: Coal | C6: Coal mine | D6: =IF(F6=0,E6,F6) -> 143 | E6: 143 | F6: =IFERROR(VLOOKUP(C6,TblAPIMines,2,FALSE),0) -> 0 | G6: =IF(I6=0,H6*$G$20/100,I6*$G$20/100) -> 270153.66 | H6: 275667 | I6: =IFERROR(VLOOKUP(C6,TblAPIMines,5,FALSE),0) -> 0 | K6: Concrete factory | L6: =IF(P6="NO",0,M6) -> 156 | M6: =IF(O6=0,N6,O6) -> 156 | N6: 156 | O6: =IFERROR(VLOOKUP(K6,TblAPIFactory,2,FALSE),0) -> 0 | P6: Yes | R6: Casino | S6: =IF(U6=0,T6,U6) -> 10 | T6: 10 | U6: =IFERROR(VLOOKUP(R6,TblAPISpecial,2,FALSE),0) -> 0 | W6: 9 | Y6: Chalcopyrite | Z6: =IF(AB6=0,AA6,AB6) -> 23 | AA6: 23 | AB6: =IFERROR(VLOOKUP(Y6,TblAPIWarehouse,2,FALSE),0) -> 0
B7: Chalcopyrite | C7: Copper mine | D7: =IF(F7=0,E7,F7) -> 0 | E7: 0 | F7: =IFERROR(VLOOKUP(C7,TblAPIMines,2,FALSE),0) -> 0 | G7: =IF(I7=0,H7*$G$20/100,I7*$G$20/100) -> 0 | H7: 0 | I7: =IFERROR(VLOOKUP(C7,TblAPIMines,5,FALSE),0) -> 0 | K7: Fertilizer factory | L7: =IF(P7="NO",0,M7) -> 64 | M7: =IF(O7=0,N7,O7) -> 64 | N7: 64 | O7: =IFERROR(VLOOKUP(K7,TblAPIFactory,2,FALSE),0) -> 0 | P7: Yes | R7: Museum | S7: =IF(U7=0,T7,U7) -> 10 | T7: 10 | U7: =IFERROR(VLOOKUP(R7,TblAPISpecial,2,FALSE),0) -> 0 | W7: ='API Raw'!S11 -> 0 | Y7: Clay | Z7: =IF(AB7=0,AA7,AB7) -> 126 | AA7: 126 | AB7: =IFERROR(VLOOKUP(Y7,TblAPIWarehouse,2,FALSE),0) -> 0
B8: Rough diamonds | C8: Diamond mine | D8: =IF(F8=0,E8,F8) -> 478 | E8: 478 | F8: =IFERROR(VLOOKUP(C8,TblAPIMines,2,FALSE),0) -> 0 | G8: =IF(I8=0,H8*$G$20/100,I8*$G$20/100) -> 5174400 | H8: 5280000 | I8: =IFERROR(VLOOKUP(C8,TblAPIMines,5,FALSE),0) -> 0 | K8: Ironworks | L8: =IF(P8="NO",0,M8) -> 65 | M8: =IF(O8=0,N8,O8) -> 65 | N8: 65 | O8: =IFERROR(VLOOKUP(K8,TblAPIFactory,2,FALSE),0) -> 0 | P8: Yes | R8: Training camp | S8: =IF(U8=0,T8,U8) -> 10 | T8: 10 | U8: =IFERROR(VLOOKUP(R8,TblAPISpecial,2,FALSE),0) -> 0 | Y8: Coal | Z8: =IF(AB8=0,AA8,AB8) -> 50 | AA8: 50 | AB8: =IFERROR(VLOOKUP(Y8,TblAPIWarehouse,2,FALSE),0) -> 0
B9: Gravel | C9: Gravel pit | D9: =IF(F9=0,E9,F9) -> 0 | E9: 0 | F9: =IFERROR(VLOOKUP(C9,TblAPIMines,2,FALSE),0) -> 0 | G9: =IF(I9=0,H9*$G$20/100,I9*$G$20/100) -> 0 | H9: 0 | I9: =IFERROR(VLOOKUP(C9,TblAPIMines,5,FALSE),0) -> 0 | K9: Oil refinery | L9: =IF(P9="NO",0,M9) -> 63 | M9: =IF(O9=0,N9,O9) -> 63 | N9: 63 | O9: =IFERROR(VLOOKUP(K9,TblAPIFactory,2,FALSE),0) -> 0 | P9: Yes | R9: Recycling plant | S9: =IF(U9=0,T9,U9) -> 10 | T9: 10 | U9: =IFERROR(VLOOKUP(R9,TblAPISpecial,2,FALSE),0) -> 0 | Y9: Crude oil | Z9: =IF(AB9=0,AA9,AB9) -> 35 | AA9: 35 | AB9: =IFERROR(VLOOKUP(Y9,TblAPIWarehouse,2,FALSE),0) -> 0
B10: Ilmenite | C10: Ilmenite mine | D10: =IF(F10=0,E10,F10) -> 0 | E10: 0 | F10: =IFERROR(VLOOKUP(C10,TblAPIMines,2,FALSE),0) -> 0 | G10: =IF(I10=0,H10*$G$20/100,I10*$G$20/100) -> 0 | H10: 0 | I10: =IFERROR(VLOOKUP(C10,TblAPIMines,5,FALSE),0) -> 0 | K10: Glazier's workshop | L10: =IF(P10="NO",0,M10) -> 47 | M10: =IF(O10=0,N10,O10) -> 47 | N10: 47 | O10: =IFERROR(VLOOKUP(K10,TblAPIFactory,2,FALSE),0) -> 0 | P10: Yes | R10: Law firm | S10: =IF(U10=0,T10,U10) -> 10 | T10: 10 | U10: =IFERROR(VLOOKUP(R10,TblAPISpecial,2,FALSE),0) -> 0 | Y10: Gold ore | Z10: =IF(AB10=0,AA10,AB10) -> 52 | AA10: 52 | AB10: =IFERROR(VLOOKUP(Y10,TblAPIWarehouse,2,FALSE),0) -> 0
B11: Iron ore | C11: Iron ore mine | D11: =IF(F11=0,E11,F11) -> 141 | E11: 141 | F11: =IFERROR(VLOOKUP(C11,TblAPIMines,2,FALSE),0) -> 0 | G11: =IF(I11=0,H11*$G$20/100,I11*$G$20/100) -> 132299.02 | H11: 134999 | I11: =IFERROR(VLOOKUP(C11,TblAPIMines,5,FALSE),0) -> 0 | K11: Copper refinery | L11: =IF(P11="NO",0,M11) -> 42 | M11: =IF(O11=0,N11,O11) -> 42 | N11: 42 | O11: =IFERROR(VLOOKUP(K11,TblAPIFactory,2,FALSE),0) -> 0 | P11: Yes | R11: Mafia HQ | S11: =IF(U11=0,T11,U11) -> 10 | T11: 10 | U11: =IFERROR(VLOOKUP(R11,TblAPISpecial,2,FALSE),0) -> 0 | Y11: Gravel | Z11: =IF(AB11=0,AA11,AB11) -> 60 | AA11: 60 | AB11: =IFERROR(VLOOKUP(Y11,TblAPIWarehouse,2,FALSE),0) -> 0
B12: Lithium ore | C12: Lithium ore mine | D12: =IF(F12=0,E12,F12) -> 257 | E12: 257 | F12: =IFERROR(VLOOKUP(C12,TblAPIMines,2,FALSE),0) -> 0 | G12: =IF(I12=0,H12*$G$20/100,I12*$G$20/100) -> 3194800 | H12: 3260000 | I12: =IFERROR(VLOOKUP(C12,TblAPIMines,5,FALSE),0) -> 0 | K12: Insecticide factory | L12: =IF(P12="NO",0,M12) -> 38 | M12: =IF(O12=0,N12,O12) -> 38 | N12: 38 | O12: =IFERROR(VLOOKUP(K12,TblAPIFactory,2,FALSE),0) -> 0 | P12: Yes | R12: Hospital | S12: =IF(U12=0,T12,U12) -> 10 | T12: 10 | U12: =IFERROR(VLOOKUP(R12,TblAPISpecial,2,FALSE),0) -> 0 | Y12: Ilmenite | Z12: =IF(AB12=0,AA12,AB12) -> 37 | AA12: 37 | AB12: =IFERROR(VLOOKUP(Y12,TblAPIWarehouse,2,FALSE),0) -> 0
B13: Quartz sand | C13: Sand mine | D13: =IF(F13=0,E13,F13) -> 0 | E13: 0 | F13: =IFERROR(VLOOKUP(C13,TblAPIMines,2,FALSE),0) -> 0 | G13: =IF(I13=0,H13*$G$20/100,I13*$G$20/100) -> 0 | H13: 0 | I13: =IFERROR(VLOOKUP(C13,TblAPIMines,5,FALSE),0) -> 0 | K13: Aluminium factory | L13: =IF(P13="NO",0,M13) -> 46 | M13: =IF(O13=0,N13,O13) -> 46 | N13: 46 | O13: =IFERROR(VLOOKUP(K13,TblAPIFactory,2,FALSE),0) -> 0 | P13: Yes | R13: Drone research | S13: =IF(U13=0,T13,U13) -> 10 | T13: 10 | U13: =IFERROR(VLOOKUP(R13,TblAPISpecial,2,FALSE),0) -> 0 | Y13: Iron ore | Z13: =IF(AB13=0,AA13,AB13) -> 51 | AA13: 51 | AB13: =IFERROR(VLOOKUP(Y13,TblAPIWarehouse,2,FALSE),0) -> 0
B14: Silver ore | C14: Silver mine | D14: =IF(F14=0,E14,F14) -> 13 | E14: 13 | F14: =IFERROR(VLOOKUP(C14,TblAPIMines,2,FALSE),0) -> 0 | G14: =IF(I14=0,H14*$G$20/100,I14*$G$20/100) -> 32797.66 | H14: 33467 | I14: =IFERROR(VLOOKUP(C14,TblAPIMines,5,FALSE),0) -> 0 | K14: Plastic factory | L14: =IF(P14="NO",0,M14) -> 41 | M14: =IF(O14=0,N14,O14) -> 41 | N14: 41 | O14: =IFERROR(VLOOKUP(K14,TblAPIFactory,2,FALSE),0) -> 0 | P14: Yes | R14: Service center | S14: =IF(U14=0,T14,U14) -> 10 | T14: 10 | U14: =IFERROR(VLOOKUP(R14,TblAPISpecial,2,FALSE),0) -> 0 | Y14: Limestone | Z14: =IF(AB14=0,AA14,AB14) -> 64 | AA14: 64 | AB14: =IFERROR(VLOOKUP(Y14,TblAPIWarehouse,2,FALSE),0) -> 0
B15: Bauxite | C15: Bauxite mine | D15: =IF(F15=0,E15,F15) -> 6 | E15: 6 | F15: =IFERROR(VLOOKUP(C15,TblAPIMines,2,FALSE),0) -> 0 | G15: =IF(I15=0,H15*$G$20/100,I15*$G$20/100) -> 7239.26 | H15: 7387 | I15: =IFERROR(VLOOKUP(C15,TblAPIMines,5,FALSE),0) -> 0 | K15: Lithium refinery | L15: =IF(P15="NO",0,M15) -> 36 | M15: =IF(O15=0,N15,O15) -> 36 | N15: 36 | O15: =IFERROR(VLOOKUP(K15,TblAPIFactory,2,FALSE),0) -> 0 | P15: Yes | R15: HR Department | S15: =IF(U15=0,T15,U15) -> 10 | T15: 10 | U15: =IFERROR(VLOOKUP(R15,TblAPISpecial,2,FALSE),0) -> 0 | Y15: Lithium ore | Z15: =IF(AB15=0,AA15,AB15) -> 120 | AA15: 120 | AB15: =IFERROR(VLOOKUP(Y15,TblAPIWarehouse,2,FALSE),0) -> 0
B16: Crude oil | C16: Oil derrick | D16: =IF(F16=0,E16,F16) -> 16 | E16: 16 | F16: =IFERROR(VLOOKUP(C16,TblAPIMines,2,FALSE),0) -> 0 | G16: =IF(I16=0,H16*$G$20/100,I16*$G$20/100) -> 6979.56 | H16: 7122 | I16: =IFERROR(VLOOKUP(C16,TblAPIMines,5,FALSE),0) -> 0 | K16: Battery factory | L16: =IF(P16="NO",0,M16) -> 17 | M16: =IF(O16=0,N16,O16) -> 17 | N16: 17 | O16: =IFERROR(VLOOKUP(K16,TblAPIFactory,2,FALSE),0) -> 0 | P16: Yes | R16: Haulage firm | S16: =IF(U16=0,T16,U16) -> 10 | T16: 10 | U16: =IFERROR(VLOOKUP(R16,TblAPISpecial,2,FALSE),0) -> 0 | Y16: Quartz sand | Z16: =IF(AB16=0,AA16,AB16) -> 38 | AA16: 38 | AB16: =IFERROR(VLOOKUP(Y16,TblAPIWarehouse,2,FALSE),0) -> 0
B17: Gold ore | C17: Gold mine | D17: =IF(F17=0,E17,F17) -> 64 | E17: 64 | F17: =IFERROR(VLOOKUP(C17,TblAPIMines,2,FALSE),0) -> 0 | G17: =IF(I17=0,H17*$G$20/100,I17*$G$20/100) -> 354553.22 | H17: 361789 | I17: =IFERROR(VLOOKUP(C17,TblAPIMines,5,FALSE),0) -> 0 | K17: Arms factory | L17: =IF(P17="NO",0,M17) -> 20 | M17: =IF(O17=0,N17,O17) -> 20 | N17: 20 | O17: =IFERROR(VLOOKUP(K17,TblAPIFactory,2,FALSE),0) -> 0 | P17: Yes | R17: Fire Station | S17: =IF(U17=0,T17,U17) -> 1 | T17: 1 | U17: =IFERROR(VLOOKUP(R17,TblAPISpecial,2,FALSE),0) -> 0 | Y17: Rough diamonds | Z17: =IF(AB17=0,AA17,AB17) -> 152 | AA17: 152 | AB17: =IFERROR(VLOOKUP(Y17,TblAPIWarehouse,2,FALSE),0) -> 0
B18: Limestone | C18: Limestone quarry | D18: =IF(F18=0,E18,F18) -> 4 | E18: 4 | F18: =IFERROR(VLOOKUP(C18,TblAPIMines,2,FALSE),0) -> 0 | G18: =IF(I18=0,H18*$G$20/100,I18*$G$20/100) -> 3686.76 | H18: 3762 | I18: =IFERROR(VLOOKUP(C18,TblAPIMines,5,FALSE),0) -> 0 | K18: Silicon refinery | L18: =IF(P18="NO",0,M18) -> 0 | M18: =IF(O18=0,N18,O18) -> 5 | N18: 5 | O18: =IFERROR(VLOOKUP(K18,TblAPIFactory,2,FALSE),0) -> 0 | P18: No | R18: Seismology Centre | S18: =IF(U18=0,T18,U18) -> 2 | T18: 2 | U18: =IFERROR(VLOOKUP(R18,TblAPISpecial,2,FALSE),0) -> 0 | Y18: Silver ore | Z18: =IF(AB18=0,AA18,AB18) -> 40 | AA18: 40 | AB18: =IFERROR(VLOOKUP(Y18,TblAPIWarehouse,2,FALSE),0) -> 0
K19: Electronics factory | L19: =IF(P19="NO",0,M19) -> 36 | M19: =IF(O19=0,N19,O19) -> 36 | N19: 36 | O19: =IFERROR(VLOOKUP(K19,TblAPIFactory,2,FALSE),0) -> 0 | P19: Yes | Y19: Aluminium | Z19: =IF(AB19=0,AA19,AB19) -> 69 | AA19: 69 | AB19: =IFERROR(VLOOKUP(Y19,TblAPIWarehouse,2,FALSE),0) -> 0
B20: TOTAL | D20: =SUM(D5:D18) -> 1147 | E20: =SUM(E5:E19) -> 1147 | G20: =AVERAGE(100-1/F24*4,100) -> 98 | H20: =SUM(H5:H19) -> 9400769 | I20: =SUM(I5:I19) -> 0 | K20: Titanium refinery | L20: =IF(P20="NO",0,M20) -> 21 | M20: =IF(O20=0,N20,O20) -> 21 | N20: 21 | O20: =IFERROR(VLOOKUP(K20,TblAPIFactory,2,FALSE),0) -> 0 | P20: Yes | Y20: Batteries | Z20: =IF(AB20=0,AA20,AB20) -> 23 | AA20: 23 | AB20: =IFERROR(VLOOKUP(Y20,TblAPIWarehouse,2,FALSE),0) -> 0
K21: Medical technology Inc. | L21: =IF(P21="NO",0,M21) -> 29 | M21: =IF(O21=0,N21,O21) -> 29 | N21: 29 | O21: =IFERROR(VLOOKUP(K21,TblAPIFactory,2,FALSE),0) -> 0 | P21: Yes | Y21: Bricks | Z21: =IF(AB21=0,AA21,AB21) -> 190 | AA21: 190 | AB21: =IFERROR(VLOOKUP(Y21,TblAPIWarehouse,2,FALSE),0) -> 0
B22: Maintenance | C22: fill from mine overview | K22: Silver refinery | L22: =IF(P22="NO",0,M22) -> 12 | M22: =IF(O22=0,N22,O22) -> 12 | N22: 12 | O22: =IFERROR(VLOOKUP(K22,TblAPIFactory,2,FALSE),0) -> 0 | P22: Yes | Y22: Concrete | Z22: =IF(AB22=0,AA22,AB22) -> 156 | AA22: 156 | AB22: =IFERROR(VLOOKUP(Y22,TblAPIWarehouse,2,FALSE),0) -> 0
B23: Expert Cost | C23: MK Cost | D23: Individual | E23: Per Day times. | K23: Gold refinery | L23: =IF(P23="NO",0,M23) -> 21 | M23: =IF(O23=0,N23,O23) -> 21 | N23: 21 | O23: =IFERROR(VLOOKUP(K23,TblAPIFactory,2,FALSE),0) -> 0 | P23: Yes | Y23: Copper | Z23: =IF(AB23=0,AA23,AB23) -> 35 | AA23: 35 | AB23: =IFERROR(VLOOKUP(Y23,TblAPIWarehouse,2,FALSE),0) -> 0
B24: 7570000000 | C24: =E20*VLOOKUP("Maintenance kit",TblMarket,5,FALSE) -> #N/A | D24: =B24/3 -> 2.5233333e+09 | F24: 1 | K24: Goldsmith | L24: =IF(P24="NO",0,M24) -> 48 | M24: =IF(O24=0,N24,O24) -> 48 | N24: 48 | O24: =IFERROR(VLOOKUP(K24,TblAPIFactory,2,FALSE),0) -> 0 | P24: Yes | Y24: Electronics | Z24: =IF(AB24=0,AA24,AB24) -> 50 | AA24: 50 | AB24: =IFERROR(VLOOKUP(Y24,TblAPIWarehouse,2,FALSE),0) -> 0
B25: No | C25: No | D25: No | E25: How many times | K25: Drone shipyard | L25: =IF(P25="NO",0,M25) -> 0 | M25: =IF(O25=0,N25,O25) -> 0 | N25: 0 | O25: =IFERROR(VLOOKUP(K25,TblAPIFactory,2,FALSE),0) -> 0 | P25: Yes | Y25: Fertilizer | Z25: =IF(AB25=0,AA25,AB25) -> 36 | AA25: 36 | AB25: =IFERROR(VLOOKUP(Y25,TblAPIWarehouse,2,FALSE),0) -> 0
B26: =(IF(B25="Yes",B24,0))*$F$24 -> 0 | C26: =(IF(C25="Yes",C24,0))*$F$24 -> 0 | D26: =(IF(D25="Yes",D24,0))*$F$24 -> 0 | E26: per day. | K26: Truck plant | L26: =IF(P26="NO",0,M26) -> 10 | M26: =IF(O26=0,N26,O26) -> 10 | N26: 10 | O26: =IFERROR(VLOOKUP(K26,TblAPIFactory,2,FALSE),0) -> 0 | P26: Yes | Y26: Fossil fuel | Z26: =IF(AB26=0,AA26,AB26) -> 102 | AA26: 102 | AB26: =IFERROR(VLOOKUP(Y26,TblAPIWarehouse,2,FALSE),0) -> 0
E27: Use a fraction if less | Y27: Glass | Z27: =IF(AB27=0,AA27,AB27) -> 84 | AA27: 84 | AB27: =IFERROR(VLOOKUP(Y27,TblAPIWarehouse,2,FALSE),0) -> 0
E28: than once per day | Y28: Gold | Z28: =IF(AB28=0,AA28,AB28) -> 20 | AA28: 20 | AB28: =IFERROR(VLOOKUP(Y28,TblAPIWarehouse,2,FALSE),0) -> 0
E29: i.e. .5 for every other | Y29: Insecticides | Z29: =IF(AB29=0,AA29,AB29) -> 43 | AA29: 43 | AB29: =IFERROR(VLOOKUP(Y29,TblAPIWarehouse,2,FALSE),0) -> 0
E30: List of likely inputs | Y30: Jewellery | Z30: =IF(AB30=0,AA30,AB30) -> 28 | AA30: 28 | AB30: =IFERROR(VLOOKUP(Y30,TblAPIWarehouse,2,FALSE),0) -> 0
E31: 2 = 2x/day | Y31: Lithium | Z31: =IF(AB31=0,AA31,AB31) -> 26 | AA31: 26 | AB31: =IFERROR(VLOOKUP(Y31,TblAPIWarehouse,2,FALSE),0) -> 0
E32: 1 = 1/day | Y32: Medical technology | Z32: =IF(AB32=0,AA32,AB32) -> 17 | AA32: 17 | AB32: =IFERROR(VLOOKUP(Y32,TblAPIWarehouse,2,FALSE),0) -> 0
E33: .5 = every other day | Y33: Plastics | Z33: =IF(AB33=0,AA33,AB33) -> 59 | AA33: 59 | AB33: =IFERROR(VLOOKUP(Y33,TblAPIWarehouse,2,FALSE),0) -> 0
E34: .33 = every third d | Y34: Scan drones | Z34: =IF(AB34=0,AA34,AB34) -> 1 | AA34: 1 | AB34: =IFERROR(VLOOKUP(Y34,TblAPIWarehouse,2,FALSE),0) -> 0
E35: .25 = every fourth d | Y35: Silicon | Z35: =IF(AB35=0,AA35,AB35) -> 16 | AA35: 16 | AB35: =IFERROR(VLOOKUP(Y35,TblAPIWarehouse,2,FALSE),0) -> 0
E36: .2 = every fifth day | Y36: Silver | Z36: =IF(AB36=0,AA36,AB36) -> 201 | AA36: 201 | AB36: =IFERROR(VLOOKUP(Y36,TblAPIWarehouse,2,FALSE),0) -> 0
Y37: Steel | Z37: =IF(AB37=0,AA37,AB37) -> 64 | AA37: 64 | AB37: =IFERROR(VLOOKUP(Y37,TblAPIWarehouse,2,FALSE),0) -> 0
Y38: Titanium | Z38: =IF(AB38=0,AA38,AB38) -> 32 | AA38: 32 | AB38: =IFERROR(VLOOKUP(Y38,TblAPIWarehouse,2,FALSE),0) -> 0
Y39: Trucks | Z39: =IF(AB39=0,AA39,AB39) -> 30 | AA39: 30 | AB39: =IFERROR(VLOOKUP(Y39,TblAPIWarehouse,2,FALSE),0) -> 0
Y40: Weapons | Z40: =IF(AB40=0,AA40,AB40) -> 15 | AA40: 15 | AB40: =IFERROR(VLOOKUP(Y40,TblAPIWarehouse,2,FALSE),0) -> 0

Sheet API INPUTS
A1: factoryID | B1: name | C1: lvl | D1: strike | F1: itemID | G1: itemname | H1: level | I1: amount | K1: specbID | L1: name | M1: lvl | O1: itemID | P1: itemname | Q1: iconURL | S1: questID | T1: title | U1: descr | V1: status | W1: progress | X1: missiongoal | Y1: durHours | Z1: rewarditem | AA1: rewardamount | AB1: penalty | AC1: cooldown | AD1: starttime | AE1: endtime | AF1: intervalDays | AG1: thumb | AI1: itemID | AJ1: itemName | AK1: factoryID | AL1: factoryName | AM1: baseOutputPerHour | AN1: outputPerCycle | AO1: creditsPerCycle | AP1: itemID1 | AQ1: item1QtyPerCycle | AR1: itemID2 | AS1: item2QtyPerCycle | AT1: itemID3 | AU1: item3QtyPerCycle | AW1: mineID | AX1: lat | AY1: lon | AZ1: HQboost | BA1: fullrate | BB1: rawrate | BC1: techfactor | BD1: name | BE1: builddate | BF1: lastmaintenance | BG1: condition | BH1: resourceName | BI1: resourceID | BJ1: lastenemyaction | BK1: def1 | BL1: def2 | BM1: def3 | BN1: attackpenalty | BO1: attackcount | BP1: attacklost | BQ1: quality | BR1: qualityInclTU | BT1: itemID | BU1: itemName | BV1: KIprice | BW1: price | BX1: unixts
A2: 6 | B2: Concrete Factory | C2: 14 | D2: no | F2: 1 | G2: credits | H2: 1 | I2: 90268970344 | K2: 65 | L2: Museum | M2: 2 | O2: 1 | P2: credits | Q2: https://api.resources-game.ch/resimg/res1.png | S2: 9 | T2: Bob The Builder | U2: Build {} mines | V2: 0 | W2: 0 | X2: 470 | Y2: 96 | Z2: 48 | AA2: 10 | AB2: 39968000000 | AC2: 0 | AD2: 0 | AE2: 0 | AF2: 7 | AG2: https://appweb.resources-game.ch/webcontent/img/questimg/schauwieschoenichbau.jpg | AI2: 7 | AJ2: Concrete | AK2: 6 | AL2: Concrete Factory | AM2: 2100 | AN2: 14 | AO2: 20 | AP2: 3 | AQ2: 3 | AR2: 20 | AS2: 2 | AW2: 4 | AX2: 48.243971 | AY2: 16.380043 | AZ2: 1 | BA2: 1122 | BB2: 1122 | BC2: 1 | BD2: Clay Pit | BE2: 1771686087 | BF2: 1772135664 | BG2: 0.971543 | BH2: Clay | BI2: 2 | BJ2: 1771686087 | BK2: 200 | BL2: 5 | BM2: 2 | BN2: 1 | BO2: 0 | BP2: 0 | BQ2: 0.7333 | BR2: 0.7333 | BT2: 2 | BU2: Clay | BV2: 350 | BW2: 354 | BX2: 1772203036
A3: 23 | B3: Fertilizer Factory | C3: 6 | D3: no | F3: 2 | G3: Clay | H3: 30 | I3: 64622 | K3: 97 | L3: Training Camp | M3: 2 | O3: 2 | P3: Clay | Q3: https://api.resources-game.ch/resimg/res2.png | S3: 11 | T3: Need clay! | U3: Sell {}m3 clay | V3: 0 | W3: 0 | X3: 1097300 | Y3: 24 | Z3: 44 | AA3: 40 | AB3: 31085000000 | AC3: 159719 | AD3: 0 | AE3: 0 | AF3: 2 | AG3: https://appweb.resources-game.ch/webcontent/img/questimg/lehmbedarf.jpg | AI3: 22 | AJ3: Fertilizer | AK3: 23 | AL3: Fertilizer Factory | AM3: 1210 | AN3: 11 | AO3: 90 | AP3: 20 | AQ3: 8 | AW3: 4 | AX3: 48.243914 | AY3: 16.380455 | AZ3: 1 | BA3: 966 | BB3: 966 | BC3: 1 | BD3: Clay Pit | BE3: 1771686096 | BF3: 1772135664 | BG3: 0.971543 | BH3: Clay | BI3: 2 | BJ3: 1771686096 | BK3: 200 | BL3: 5 | BM3: 2 | BN3: 1 | BO3: 0 | BP3: 0 | BQ3: 0.6314 | BR3: 0.6314 | BT3: 3 | BU3: Gravel | BV3: 474 | BW3: 478 | BX3: 1772203036
A4: 25 | B4: Brick Factory | C4: 47 | D4: no | F4: 3 | G4: Gravel | H4: 10 | I4: 317038 | K4: 62 | L4: Casino | M4: 3 | O4: 3 | P4: Gravel | Q4: https://api.resources-game.ch/resimg/res3.png | S4: 12 | T4: Collectoritis | U4: Collect {} crates | V4: 0 | W4: 0 | X4: 420 | Y4: 144 | Z4: 46 | AA4: 30 | AB4: 65376000000 | AC4: 0 | AD4: 0 | AE4: 0 | AF4: 6 | AG4: https://appweb.resources-game.ch/webcontent/img/questimg/altersammler.jpg | AI4: 24 | AJ4: Bricks | AK4: 25 | AL4: Brick Factory | AM4: 800 | AN4: 2 | AO4: 10 | AP4: 2 | AQ4: 3 | AW4: 4 | AX4: 48.234626 | AY4: 16.383156 | AZ4: 1 | BA4: 1122 | BB4: 1122 | BC4: 1 | BD4: Clay Pit | BE4: 1771686882 | BF4: 1772135664 | BG4: 0.971543 | BH4: Clay | BI4: 2 | BJ4: 1771686882 | BK4: 200 | BL4: 5 | BM4: 2 | BN4: 1 | BO4: 0 | BP4: 0 | BQ4: 0.7333 | BR4: 0.7333 | BT4: 7 | BU4: Concrete | BV4: 4556 | BW4: 5262 | BX4: 1772203036
A5: 29 | B5: Insecticide Factory | C5: 1 | D5: no | F5: 7 | G5: Concrete | H5: 9 | I5: 216299 | O5: 4 | P5: Clay Pit | S5: 14 | T5: Scan junkie | U5: Scan for deposits {} times | V5: 0 | W5: 0 | X5: 25 | Y5: 48 | Z5: 45 | AA5: 10 | AB5: 2247000000 | AC5: 217908 | AD5: 0 | AE5: 0 | AF5: 3 | AG5: https://appweb.resources-game.ch/webcontent/img/questimg/scanneumgebung.jpg | AI5: 28 | AJ5: Insecticides | AK5: 29 | AL5: Insecticide Factory | AM5: 3500 | AN5: 35 | AO5: 2400 | AP5: 36 | AQ5: 1 | AR5: 20 | AS5: 3 | AW5: 4 | AX5: 48.198863 | AY5: 16.386327 | AZ5: 1 | BA5: 966 | BB5: 966 | BC5: 1 | BD5: Clay Pit | BE5: 1771687402 | BF5: 1772135664 | BG5: 0.971543 | BH5: Clay | BI5: 2 | BJ5: 1771687402 | BK5: 200 | BL5: 5 | BM5: 2 | BN5: 1 | BO5: 0 | BP5: 0 | BQ5: 0.6314 | BR5: 0.6314 | BT5: 8 | BU5: Coal | BV5: 2426 | BW5: 2452 | BX5: 1772203036
A6: 31 | B6: Ironworks | C6: 3 | D6: no | F6: 8 | G6: Coal | H6: 8 | I6: 294499 | O6: 5 | P6: Gravel Pit | S6: 17 | T6: Warehouse boss | U6: Expand your warehouses {} times | V6: 0 | W6: 0 | X6: 104 | Y6: 96 | Z6: 115 | AA6: 13000 | AB6: 415636000000 | AC6: 0 | AD6: 0 | AE6: 0 | AF6: 7 | AG6: https://appweb.resources-game.ch/webcontent/img/questimg/lager.jpg | AI6: 30 | AJ6: Steel | AK6: 31 | AL6: Ironworks | AM6: 450 | AN6: 1 | AO6: 350 | AP6: 13 | AQ6: 7 | AR6: 8 | AS6: 10 | AW6: 4 | AX6: 48.138206 | AY6: 16.445265 | AZ6: 1 | BA6: 996 | BB6: 996 | BC6: 1 | BD6: Clay Pit | BE6: 1771724868 | BF6: 1772135664 | BG6: 0.971543 | BH6: Clay | BI6: 2 | BJ6: 1771724868 | BK6: 200 | BL6: 5 | BM6: 2 | BN6: 1 | BO6: 0 | BP6: 0 | BQ6: 0.651 | BR6: 0.651 | BT6: 10 | BU6: Crude Oil | BV6: 2519 | BW6: 0 | BX6: 1772203036
A7: 33 | B7: Aluminium Factory | C7: 1 | D7: no | F7: 10 | G7: Crude Oil | H7: 3 | I7: 110 | O7: 6 | P7: Concrete Factory | Q7: https://api.resources-game.ch/resimg/res6.png | S7: 22 | T7: Stinginess is awesome! | U7: Perform {} free (="boss in range") maintenances | V7: 0 | W7: 0 | X7: 130 | Y7: 168 | Z7: 43 | AA7: 390 | AB7: 44341000000 | AC7: 0 | AD7: 0 | AE7: 0 | AF7: 7 | AG7: https://appweb.resources-game.ch/webcontent/img/questimg/geizistgeil.jpg | AI7: 32 | AJ7: Aluminium | AK7: 33 | AL7: Aluminium Factory | AM7: 320 | AN7: 4 | AO7: 5000 | AP7: 12 | AQ7: 24 | AW7: 4 | AX7: 48.140479 | AY7: 16.434311 | AZ7: 1 | BA7: 1188 | BB7: 1188 | BC7: 1 | BD7: Clay Pit | BE7: 1771724905 | BF7: 1772135664 | BG7: 0.971543 | BH7: Clay | BI7: 2 | BJ7: 1771724905 | BK7: 200 | BL7: 5 | BM7: 2 | BN7: 1 | BO7: 0 | BP7: 0 | BQ7: 0.7765 | BR7: 0.7765 | BT7: 12 | BU7: Bauxite | BV7: 2045 | BW7: 2086 | BX7: 1772203036
A8: 37 | B8: Copper Refinery | C8: 1 | D8: no | F8: 12 | G8: Bauxite | H8: 6 | I8: 94043 | O8: 7 | P8: Concrete | Q8: https://api.resources-game.ch/resimg/res7.png | S8: 31 | T8: Need more insecticides! | U8: Sell {}m3 insecticides | V8: 0 | W8: 0 | X8: 1441650 | Y8: 72 | Z8: 42 | AA8: 1 | AB8: 95776000000 | AC8: 0 | AD8: 0 | AE8: 0 | AF8: 2 | AG8: https://appweb.resources-game.ch/webcontent/img/questimg/insektizidebedarf.jpg | AI8: 35 | AJ8: Silver | AK8: 34 | AL8: Silver Refinery | AM8: 3000 | AN8: 50 | AO8: 10000 | AP8: 15 | AQ8: 8 | AW8: 4 | AX8: 48.146065 | AY8: 16.430753 | AZ8: 1 | BA8: 1044 | BB8: 1044 | BC8: 1 | BD8: Clay Pit | BE8: 1771724934 | BF8: 1772135664 | BG8: 0.971543 | BH8: Clay | BI8: 2 | BJ8: 1771724934 | BK8: 200 | BL8: 5 | BM8: 2 | BN8: 1 | BO8: 0 | BP8: 0 | BQ8: 0.6824 | BR8: 0.6824 | BT8: 13 | BU8: Iron Ore | BV8: 1267 | BW8: 1499 | BX8: 1772203036
A9: 39 | B9: Oil Refinery | C9: 1 | D9: no | F9: 13 | G9: Iron Ore | H9: 3 | I9: 800 | O9: 8 | P9: Coal | Q9: https://api.resources-game.ch/resimg/res8.png | S9: 32 | T9: Time is Money | U9: Trigger {} instant-productions (use a Giant Diamond to hasten production) | V9: 0 | W9: 0 | X9: 10 | Y9: 144 | Z9: 84 | AA9: 52000 | AB9: 220067000000 | AC9: 0 | AD9: 0 | AE9: 0 | AF9: 4 | AG9: https://appweb.resources-game.ch/webcontent/img/questimg/zeitistgeld.jpg | AI9: 36 | AJ9: Copper | AK9: 37 | AL9: Copper Refinery | AM9: 270 | AN9: 3 | AO9: 2500 | AP9: 26 | AQ9: 9 | AW9: 4 | AX9: 48.146716 | AY9: 16.430304 | AZ9: 1 | BA9: 1476 | BB9: 1476 | BC9: 1 | BD9: Clay Pit | BE9: 1771724937 | BF9: 1772135664 | BG9: 0.971543 | BH9: Clay | BI9: 2 | BJ9: 1771724937 | BK9: 200 | BL9: 5 | BM9: 2 | BN9: 1 | BO9: 0 | BP9: 0 | BQ9: 0.9647 | BR9: 0.9647 | BT9: 14 | BU9: Gold Ore | BV9: 956 | BW9: 0 | BX9: 1772203036
A10: 61 | B10: Glazier's Workshop | C10: 1 | D10: no | F10: 20 | G10: Limestone | H10: 15 | I10: 741425 | O10: 9 | P10: Coal Mine | S10: 33 | T10: Paranoia? | U10: Assign {} units to defend your mines | V10: 0 | W10: 0 | X10: 20000 | Y10: 168 | Z10: 99 | AA10: 130 | AB10: 179657000000 | AC10: 0 | AD10: 0 | AE10: 0 | AF10: 7 | AG10: https://appweb.resources-game.ch/webcontent/img/questimg/paranoid.jpg | AI10: 38 | AJ10: Fossil Fuel | AK10: 39 | AL10: Oil Refinery | AM10: 640 | AN10: 4 | AO10: 150 | AP10: 10 | AQ10: 4 | AW10: 4 | AX10: 48.15238 | AY10: 16.426931 | AZ10: 1 | BA10: 1020 | BB10: 1020 | BC10: 1 | BD10: Clay Pit | BE10: 1771724971 | BF10: 1772135664 | BG10: 0.971543 | BH10: Clay | BI10: 2 | BJ10: 1771724971 | BK10: 200 | BL10: 5 | BM10: 2 | BN10: 1 | BO10: 0 | BP10: 0 | BQ10: 0.6667 | BR10: 0.6667 | BT10: 15 | BU10: Silver Ore | BV10: 1433 | BW10: 0 | BX10: 1772203036
A11: 63 | B11: Plastic Factory | C11: 1 | D11: no | F11: 22 | G11: Fertilizer | H11: 4 | I11: 71149 | O11: 10 | P11: Crude Oil | Q11: https://api.resources-game.ch/resimg/res10.png | S11: 35 | T11: Pimp my mine | U11: Apply {} Tech upgrades to your mines | V11: 0 | W11: 0 | X11: 300 | Y11: 168 | Z11: 44 | AA11: 30 | AB11: 20723000000 | AC11: 0 | AD11: 0 | AE11: 0 | AF11: 7 | AG11: https://appweb.resources-game.ch/webcontent/img/questimg/pimpmyfa.jpg | AI11: 51 | AJ11: Titanium | AK11: 52 | AL11: Titanium Refinery | AM11: 320 | AN11: 4 | AO11: 10000 | AP11: 49 | AQ11: 8 | AW11: 4 | AX11: 48.161225 | AY11: 16.421333 | AZ11: 1 | BA11: 1020 | BB11: 1020 | BC11: 1 | BD11: Clay Pit | BE11: 1771725073 | BF11: 1772135664 | BG11: 0.971543 | BH11: Clay | BI11: 2 | BJ11: 1771725073 | BK11: 200 | BL11: 5 | BM11: 2 | BN11: 1 | BO11: 0 | BP11: 0 | BQ11: 0.6667 | BR11: 0.6667 | BT11: 20 | BU11: Limestone | BV11: 496 | BW11: 515 | BX11: 1772203036
A12: 91 | B12: Lithium Refinery | C12: 1 | D12: no | F12: 24 | G12: Bricks | H12: 10 | I12: 41536 | O12: 11 | P12: Oil Derrick | S12: 37 | T12: Pimp my factory | U12: Upgrade your factories {} times | V12: 0 | W12: 0 | X12: 5 | Y12: 120 | Z12: 1 | AA12: 10400000000 | AB12: 20800000000 | AC12: 0 | AD12: 0 | AE12: 0 | AF12: 5 | AG12: https://appweb.resources-game.ch/webcontent/img/questimg/pimp_my_fabrik.jpg | AI12: 60 | AJ12: Glass | AK12: 61 | AL12: Glazier's Workshop | AM12: 640 | AN12: 8 | AO12: 3000 | AP12: 53 | AQ12: 6 | AR12: 38 | AS12: 8 | AT12: 20 | AU12: 4 | AW12: 4 | AX12: 48.16306 | AY12: 16.419027 | AZ12: 1 | BA12: 1176 | BB12: 1176 | BC12: 1 | BD12: Clay Pit | BE12: 1771725081 | BF12: 1772135664 | BG12: 0.971543 | BH12: Clay | BI12: 2 | BJ12: 1771725081 | BK12: 200 | BL12: 5 | BM12: 2 | BN12: 1 | BO12: 0 | BP12: 0 | BQ12: 0.7686 | BR12: 0.7686 | BT12: 22 | BU12: Fertilizer | BV12: 2169 | BW12: 0 | BX12: 1772203036
A13: 95 | B13: Battery Factory | C13: 1 | D13: no | F13: 26 | G13: Chalcopyrite | H13: 6 | I13: 150705 | O13: 12 | P13: Bauxite | Q13: https://api.resources-game.ch/resimg/res12.png | S13: 38 | T13: Maintenance | U13: Repair {} mines with maintenance kits | V13: 0 | W13: 0 | X13: 40 | Y13: 48 | Z13: 84 | AA13: 1560 | AB13: 33010000000 | AC13: 0 | AD13: 0 | AE13: 0 | AF13: 2 | AG13: https://appweb.resources-game.ch/webcontent/img/questimg/wartung.jpg | AI13: 58 | AJ13: Plastics | AK13: 63 | AL13: Plastic Factory | AM13: 1800 | AN13: 10 | AO13: 400 | AP13: 10 | AQ13: 1 | AW13: 4 | AX13: 48.163251 | AY13: 16.418665 | AZ13: 1 | BA13: 1332 | BB13: 1332 | BC13: 1 | BD13: Clay Pit | BE13: 1771725086 | BF13: 1772135664 | BG13: 0.971543 | BH13: Clay | BI13: 2 | BJ13: 1771725086 | BK13: 200 | BL13: 5 | BM13: 2 | BN13: 1 | BO13: 0 | BP13: 0 | BQ13: 0.8706 | BR13: 0.8706 | BT13: 24 | BU13: Bricks | BV13: 2795 | BW13: 3245 | BX13: 1772203036
F14: 28 | G14: Insecticides | H14: 4 | I14: 72371 | O14: 13 | P14: Iron Ore | Q14: https://api.resources-game.ch/resimg/res13.png | S14: 41 | T14: Consolation money | U14: Suffer an epidemic | V14: 0 | W14: 0 | X14: 1 | Y14: 120 | Z14: 1 | AA14: 5200000000 | AB14: 1041000000 | AC14: 0 | AD14: 0 | AE14: 0 | AF14: 0 | AG14: https://appweb.resources-game.ch/webcontent/img/questimg/trostpflaster.jpg | AI14: 67 | AJ14: Silicon | AK14: 68 | AL14: Silicon Refinery | AM14: 120 | AN14: 2 | AO14: 49500 | AP14: 53 | AQ14: 20 | AR14: 2 | AS14: 1 | AT14: 38 | AU14: 5 | AW14: 4 | AX14: 48.163554 | AY14: 16.418837 | AZ14: 1 | BA14: 1122 | BB14: 1122 | BC14: 1 | BD14: Clay Pit | BE14: 1771725089 | BF14: 1772135664 | BG14: 0.971543 | BH14: Clay | BI14: 2 | BJ14: 1771725089 | BK14: 200 | BL14: 5 | BM14: 2 | BN14: 1 | BO14: 0 | BP14: 0 | BQ14: 0.7333 | BR14: 0.7333 | BT14: 26 | BU14: Chalcopyrite | BV14: 1350 | BW14: 1350 | BX14: 1772203036
F15: 30 | G15: Steel | H15: 2 | I15: 12863 | O15: 14 | P15: Gold Ore | Q15: https://api.resources-game.ch/resimg/res14.png | S15: 42 | T15: Insurance | U15: Suffer a mine accident | V15: 0 | W15: 0 | X15: 1 | Y15: 120 | Z15: 1 | AA15: 7800000000 | AB15: 1561000000 | AC15: 0 | AD15: 0 | AE15: 0 | AF15: 0 | AG15: https://appweb.resources-game.ch/webcontent/img/questimg/insurance.jpg | AI15: 66 | AJ15: Electronics | AK15: 69 | AL15: Electronics Factory | AM15: 480 | AN15: 8 | AO15: 5000 | AP15: 58 | AQ15: 4 | AR15: 36 | AS15: 3 | AT15: 67 | AU15: 1 | AW15: 4 | AX15: 48.163342 | AY15: 16.41915 | AZ15: 1 | BA15: 1008 | BB15: 1008 | BC15: 1 | BD15: Clay Pit | BE15: 1771725093 | BF15: 1772135664 | BG15: 0.971543 | BH15: Clay | BI15: 2 | BJ15: 1771725093 | BK15: 200 | BL15: 5 | BM15: 2 | BN15: 1 | BO15: 0 | BP15: 0 | BQ15: 0.6588 | BR15: 0.6588 | BT15: 28 | BU15: Insecticides | BV15: 4259 | BW15: 4302 | BX15: 1772203036
F16: 32 | G16: Aluminium | H16: 4 | I16: 1687 | O16: 15 | P16: Silver Ore | Q16: https://api.resources-game.ch/resimg/res15.png | S16: 43 | T16: Wanderer | U16: Walk a distance of {}m (Resources must be running to count) | V16: 1 | W16: 2172 | X16: 6335 | Y16: 192 | Z16: 1 | AA16: 2600000000 | AB16: 0 | AC16: 0 | AD16: 1772097546 | AE16: 1772788746 | AF16: 1 | AG16: https://appweb.resources-game.ch/webcontent/img/questimg/wanderer.jpg | AI16: 75 | AJ16: Medical Technology | AK16: 76 | AL16: Medical Technology Inc. | AM16: 400 | AN16: 10 | AO16: 90000 | AP16: 51 | AQ16: 4 | AR16: 58 | AS16: 2 | AT16: 66 | AU16: 2 | AW16: 4 | AX16: 48.163125 | AY16: 16.419453 | AZ16: 1 | BA16: 996 | BB16: 996 | BC16: 1 | BD16: Clay Pit | BE16: 1771725097 | BF16: 1772135664 | BG16: 0.971543 | BH16: Clay | BI16: 2 | BJ16: 1771725097 | BK16: 200 | BL16: 5 | BM16: 2 | BN16: 1 | BO16: 0 | BP16: 0 | BQ16: 0.651 | BR16: 0.651 | BT16: 30 | BU16: Steel | BV16: 43334 | BW16: 49988 | BX16: 1772203036
F17: 36 | G17: Copper | H17: 4 | I17: 9276 | O17: 16 | P17: Bauxite Mine | S17: 44 | T17: Service | U17: Repair {} of someone else's mines | V17: 0 | W17: 0 | X17: 510 | Y17: 72 | Z17: 1 | AA17: 1300000000 | AB17: 1300000000 | AC17: 0 | AD17: 0 | AE17: 0 | AF17: 1 | AG17: https://appweb.resources-game.ch/webcontent/img/questimg/fremdwartung.jpg | AI17: 79 | AJ17: Gold | AK17: 80 | AL17: Gold Refinery | AM17: 240 | AN17: 3 | AO17: 20000 | AP17: 14 | AQ17: 20 | AW17: 4 | AX17: 48.178356 | AY17: 16.408769 | AZ17: 1 | BA17: 1110 | BB17: 1110 | BC17: 1 | BD17: Clay Pit | BE17: 1771725234 | BF17: 1772135664 | BG17: 0.971543 | BH17: Clay | BI17: 2 | BJ17: 1771725234 | BK17: 200 | BL17: 5 | BM17: 2 | BN17: 1 | BO17: 0 | BP17: 0 | BQ17: 0.7255 | BR17: 0.7255 | BT17: 32 | BU17: Aluminium | BV17: 91432 | BW17: 94900 | BX17: 1772203036
F18: 38 | G18: Fossil Fuel | H18: 4 | I18: 962 | O18: 17 | P18: Iron Ore Mine | S18: 50 | T18: Truck dealer | U18: Sell {} trucks | V18: 0 | W18: 0 | X18: 40000 | Y18: 48 | Z18: 1 | AA18: 3640000000 | AB18: 18200000000 | AC18: 0 | AD18: 0 | AE18: 0 | AF18: 3 | AG18: https://appweb.resources-game.ch/webcontent/img/questimg/spediteur.jpg | AI18: 84 | AJ18: Jewellery | AK18: 85 | AL18: Goldsmith | AM18: 100 | AN18: 2 | AO18: 50000 | AP18: 81 | AQ18: 1000 | AR18: 79 | AS18: 1 | AT18: 35 | AU18: 1 | AW18: 4 | AX18: 48.239368 | AY18: 16.381789 | AZ18: 1 | BA18: 1152 | BB18: 1152 | BC18: 1 | BD18: Clay Pit | BE18: 1771726134 | BF18: 1772135664 | BG18: 0.971543 | BH18: Clay | BI18: 2 | BJ18: 1771726134 | BK18: 200 | BL18: 5 | BM18: 2 | BN18: 1 | BO18: 0 | BP18: 0 | BQ18: 0.7529 | BR18: 0.7529 | BT18: 35 | BU18: Silver | BV18: 1645 | BW18: 1661 | BX18: 1772203036
F19: 40 | G19: Roman Coins | H19: 4 | I19: 32384 | O19: 18 | P19: Gold Mine | S19: 55 | T19: ...anyone need drones? | U19: Sell {} scandrones | V19: 0 | W19: 0 | X19: 400 | Y19: 48 | Z19: 1 | AA19: 1040000000 | AB19: 5200000000 | AC19: 0 | AD19: 0 | AE19: 0 | AF19: 3 | AG19: https://appweb.resources-game.ch/webcontent/img/questimg/drohnendroenen2.jpg | AI19: 92 | AJ19: Lithium | AK19: 91 | AL19: Lithium Refinery | AM19: 750 | AN19: 5 | AO19: 5000 | AP19: 90 | AQ19: 115 | AW19: 4 | AX19: 48.237487 | AY19: 16.378735 | AZ19: 1 | BA19: 1086 | BB19: 1086 | BC19: 1 | BD19: Clay Pit | BE19: 1771726816 | BF19: 1772135664 | BG19: 0.971543 | BH19: Clay | BI19: 2 | BJ19: 1771726816 | BK19: 200 | BL19: 5 | BM19: 2 | BN19: 1 | BO19: 0 | BP19: 0 | BQ19: 0.7098 | BR19: 0.7098 | BT19: 36 | BU19: Copper | BV19: 87230 | BW19: 87231 | BX19: 1772203036
F20: 41 | G20: Fossils | H20: 6 | I20: 154965 | O20: 19 | P20: Silver Mine | AI20: 93 | AJ20: Batteries | AK20: 95 | AL20: Battery Factory | AM20: 600 | AN20: 10 | AO20: 75000 | AP20: 92 | AQ20: 20 | AR20: 58 | AS20: 40 | AT20: 32 | AU20: 10 | AW20: 4 | AX20: 48.238542 | AY20: 16.377994 | AZ20: 1 | BA20: 1086 | BB20: 1086 | BC20: 1 | BD20: Clay Pit | BE20: 1771726834 | BF20: 1772135664 | BG20: 0.971543 | BH20: Clay | BI20: 2 | BJ20: 1771726834 | BK20: 200 | BL20: 5 | BM20: 2 | BN20: 1 | BO20: 0 | BP20: 0 | BQ20: 0.7098 | BR20: 0.7098 | BT20: 38 | BU20: Fossil Fuel | BV20: 28209 | BW20: 29550 | BX20: 1772203036
F21: 42 | G21: Giant Diamond | H21: 1 | I21: 5 | O21: 20 | P21: Limestone | Q21: https://api.resources-game.ch/resimg/res20.png | AI21: 87 | AJ21: Weapons | AK21: 101 | AL21: Arms Factory | AM21: 125 | AN21: 25 | AO21: 250000 | AP21: 30 | AQ21: 1 | AR21: 32 | AS21: 1 | AT21: 93 | AU21: 1 | AW21: 4 | AX21: 48.238741 | AY21: 16.377676 | AZ21: 1 | BA21: 1098 | BB21: 1098 | BC21: 1 | BD21: Clay Pit | BE21: 1771726837 | BF21: 1772135664 | BG21: 0.971543 | BH21: Clay | BI21: 2 | BJ21: 1771726837 | BK21: 200 | BL21: 5 | BM21: 2 | BN21: 1 | BO21: 0 | BP21: 0 | BQ21: 0.7176 | BR21: 0.7176 | BT21: 40 | BU21: Roman Coins | BV21: 56771 | BW21: 65651 | BX21: 1772203036
F22: 44 | G22: Tech Upgrade 1 | H22: 1 | I22: 65 | O22: 21 | P22: Limestone Quarry | AI22: 117 | AJ22: Scan Drones | AK22: 118 | AL22: Drone Shipyard | AM22: 1 | AN22: 1 | AO22: 25000000 | AP22: 66 | AQ22: 25 | AR22: 51 | AS22: 50 | AT22: 93 | AU22: 250 | AW22: 4 | AX22: 48.238961 | AY22: 16.377405 | AZ22: 1 | BA22: 1098 | BB22: 1098 | BC22: 1 | BD22: Clay Pit | BE22: 1771726840 | BF22: 1772135664 | BG22: 0.971543 | BH22: Clay | BI22: 2 | BJ22: 1771726840 | BK22: 200 | BL22: 5 | BM22: 2 | BN22: 1 | BO22: 0 | BP22: 0 | BQ22: 0.7176 | BR22: 0.7176 | BT22: 41 | BU22: Fossils | BV22: 11066 | BW22: 13954 | BX22: 1772203036
F23: 45 | G23: Tech Upgrade 2 | H23: 1 | I23: 10 | O23: 22 | P23: Fertilizer | Q23: https://api.resources-game.ch/resimg/res22.png | AI23: 124 | AJ23: Trucks | AK23: 125 | AL23: Truck plant | AM23: 100 | AN23: 50 | AO23: 2500000 | AP23: 30 | AQ23: 100 | AR23: 93 | AS23: 25 | AT23: 35 | AU23: 50 | AW23: 4 | AX23: 48.239184 | AY23: 16.377115 | AZ23: 1 | BA23: 1122 | BB23: 1122 | BC23: 1 | BD23: Clay Pit | BE23: 1771726844 | BF23: 1772135664 | BG23: 0.971543 | BH23: Clay | BI23: 2 | BJ23: 1771726844 | BK23: 200 | BL23: 5 | BM23: 2 | BN23: 1 | BO23: 0 | BP23: 0 | BQ23: 0.7333 | BR23: 0.7333 | BT23: 42 | BU23: Giant Diamond | BV23: 957950133 | BW23: 0 | BX23: 1772203036
F24: 49 | G24: Ilmenite | H24: 4 | I24: 43902 | O24: 23 | P24: Fertilizer Factory | Q24: https://api.resources-game.ch/resimg/res23.png | AW24: 4 | AX24: 48.239348 | AY24: 16.376758 | AZ24: 1 | BA24: 1272 | BB24: 1272 | BC24: 1 | BD24: Clay Pit | BE24: 1771726847 | BF24: 1772135664 | BG24: 0.971543 | BH24: Clay | BI24: 2 | BJ24: 1771726847 | BK24: 200 | BL24: 5 | BM24: 2 | BN24: 1 | BO24: 0 | BP24: 0 | BQ24: 0.8314 | BR24: 0.8314 | BT24: 43 | BU24: Maintenance Kit | BV24: 56876282 | BW24: 63428000 | BX24: 1772203036
F25: 53 | G25: Quartz Sand | H25: 8 | I25: 279676 | O25: 24 | P25: Bricks | Q25: https://api.resources-game.ch/resimg/res24.png | AW25: 4 | AX25: 48.23961 | AY25: 16.376551 | AZ25: 1 | BA25: 1230 | BB25: 1230 | BC25: 1 | BD25: Clay Pit | BE25: 1771726850 | BF25: 1772135664 | BG25: 0.971543 | BH25: Clay | BI25: 2 | BJ25: 1771726850 | BK25: 200 | BL25: 5 | BM25: 2 | BN25: 1 | BO25: 0 | BP25: 0 | BQ25: 0.8039 | BR25: 0.8039 | BT25: 44 | BU25: Tech Upgrade 1 | BV25: 79761236 | BW25: 81500000 | BX25: 1772203036
F26: 55 | G26: Copper Coins | H26: 4 | I26: 55954 | O26: 25 | P26: Brick Factory | Q26: https://api.resources-game.ch/resimg/res25.png | AW26: 4 | AX26: 48.239876 | AY26: 16.376589 | AZ26: 1 | BA26: 1332 | BB26: 1332 | BC26: 1 | BD26: Clay Pit | BE26: 1771726854 | BF26: 1772135664 | BG26: 0.971543 | BH26: Clay | BI26: 2 | BJ26: 1771726854 | BK26: 200 | BL26: 5 | BM26: 2 | BN26: 1 | BO26: 0 | BP26: 0 | BQ26: 0.8706 | BR26: 0.8706 | BT26: 45 | BU26: Tech Upgrade 2 | BV26: 224349572 | BW26: 262165702 | BX26: 1772203036
F27: 57 | G27: Old Tires | H27: 4 | I27: 54650 | O27: 26 | P27: Chalcopyrite | Q27: https://api.resources-game.ch/resimg/res26.png | AW27: 4 | AX27: 48.239867 | AY27: 16.37617 | AZ27: 1 | BA27: 1476 | BB27: 1476 | BC27: 1 | BD27: Clay Pit | BE27: 1771726857 | BF27: 1772135664 | BG27: 0.971543 | BH27: Clay | BI27: 2 | BJ27: 1771726857 | BK27: 200 | BL27: 5 | BM27: 2 | BN27: 1 | BO27: 0 | BP27: 0 | BQ27: 0.9647 | BR27: 0.9647 | BT27: 46 | BU27: Tech Upgrade 3 | BV27: 251990064 | BW27: 281171204 | BX27: 1772203036
F28: 58 | G28: Plastics | H28: 4 | I28: 51576 | O28: 27 | P28: Copper Mine | AW28: 4 | AX28: 48.240123 | AY28: 16.375953 | AZ28: 1 | BA28: 1530 | BB28: 1530 | BC28: 1 | BD28: Clay Pit | BE28: 1771726861 | BF28: 1772135664 | BG28: 0.971543 | BH28: Clay | BI28: 2 | BJ28: 1771726861 | BK28: 200 | BL28: 5 | BM28: 2 | BN28: 1 | BO28: 0 | BP28: 0 | BQ28: 1 | BR28: 1 | BT28: 48 | BU28: Tech Upgrade 4 | BV28: 104048340 | BW28: 0 | BX28: 1772203036
F29: 60 | G29: Glass | H29: 4 | I29: 31559 | O29: 28 | P29: Insecticides | Q29: https://api.resources-game.ch/resimg/res28.png | AW29: 4 | AX29: 48.240374 | AY29: 16.37608 | AZ29: 1 | BA29: 1464 | BB29: 1464 | BC29: 1 | BD29: Clay Pit | BE29: 1771726864 | BF29: 1772135664 | BG29: 0.971543 | BH29: Clay | BI29: 2 | BJ29: 1771726864 | BK29: 200 | BL29: 5 | BM29: 2 | BN29: 1 | BO29: 0 | BP29: 0 | BQ29: 0.9569 | BR29: 0.9569 | BT29: 49 | BU29: Ilmenite | BV29: 309 | BW29: 312 | BX29: 1772203036
F30: 81 | G30: Rough Diamonds | H30: 2 | I30: 4266 | O30: 29 | P30: Insecticide Factory | Q30: https://api.resources-game.ch/resimg/res29.png | AW30: 4 | AX30: 48.240379 | AY30: 16.375647 | AZ30: 1 | BA30: 1386 | BB30: 1386 | BC30: 1 | BD30: Clay Pit | BE30: 1771726868 | BF30: 1772135664 | BG30: 0.971543 | BH30: Clay | BI30: 2 | BJ30: 1771726868 | BK30: 200 | BL30: 5 | BM30: 2 | BN30: 1 | BO30: 0 | BP30: 0 | BQ30: 0.9059 | BR30: 0.9059 | BT30: 51 | BU30: Titanium | BV30: 35998 | BW30: 36155 | BX30: 1772203036
F31: 90 | G31: Lithium Ore | H31: 4 | I31: 756 | O31: 30 | P31: Steel | Q31: https://api.resources-game.ch/resimg/res30.png | AW31: 4 | AX31: 48.240651 | AY31: 16.375767 | AZ31: 1 | BA31: 1074 | BB31: 1074 | BC31: 1 | BD31: Clay Pit | BE31: 1771726871 | BF31: 1772135664 | BG31: 0.971543 | BH31: Clay | BI31: 2 | BJ31: 1771726871 | BK31: 200 | BL31: 5 | BM31: 2 | BN31: 1 | BO31: 0 | BP31: 0 | BQ31: 0.702 | BR31: 0.702 | BT31: 53 | BU31: Quartz Sand | BV31: 357 | BW31: 0 | BX31: 1772203036
F32: 92 | G32: Lithium | H32: 4 | I32: 166 | O32: 31 | P32: Ironworks | Q32: https://api.resources-game.ch/resimg/res31.png | AW32: 4 | AX32: 48.244113 | AY32: 16.379694 | AZ32: 1 | BA32: 1176 | BB32: 1176 | BC32: 1 | BD32: Clay Pit | BE32: 1771758658 | BF32: 1772135664 | BG32: 0.971543 | BH32: Clay | BI32: 2 | BJ32: 1771758658 | BK32: 200 | BL32: 5 | BM32: 2 | BN32: 1 | BO32: 0 | BP32: 0 | BQ32: 0.7686 | BR32: 0.7686 | BT32: 55 | BU32: Copper Coins | BV32: 20060 | BW32: 23355 | BX32: 1772203036
